<robot name="simple_arm" xmlns:xacro="http://wiki.ros.org/xacro">
    <link name="base_link">
        <visual>
            <geometry>
                <cylinder radius="1" length="0.5" />
            </geometry>
            <material name="gray">
                <color rgba="1 1 0.5 1" />
            </material>
        </visual>
        <collision>
            <geometry>
                <cylinder radius="1" length="0.5" />
            </geometry>
        </collision>
        <inertial>
            <mass value="0.1" />
            <origin xyz="0 0 0" rpy="0 0 0" />
            <inertia ixx="0.03" iyy="0.03" izz="0.03" ixy="0.0" ixz="0.0" iyz="0.0" />
        </inertial>
    </link>
    <joint name="joint1" type="fixed">
        <parent link="base_link" />
        <child link="link1" />
        <origin xyz="0 0 1" />
        <axis xyz="0 0 1" />
        <limit effort="5" velocity="2.0" lower="0" upper="3.14" />
    </joint>
    <link name="link1">
        <visual>
            <geometry>
                <cylinder radius="0.7" length="1.5" />
            </geometry>
            <material name="gray">
                <color rgba="1 1 0.5 1" />
            </material>
        </visual>
        <collision>
            <geometry>
                <cylinder radius="0.7" length="1.5" />
            </geometry>
        </collision>
        <inertial>
            <mass value="0.1" />
            <origin xyz="0 0 0" rpy="0 0 0" />
            <inertia ixx="0.03" iyy="0.03" izz="0.03" ixy="0.0" ixz="0.0" iyz="0.0" />
        </inertial>
    </link>
    <joint name="joint2" type="revolute">
        <parent link="link1" />
        <child link="link2" />
        <origin xyz="0 0 0.75" />
        <axis xyz="0 0 1" />
        <limit effort="5" velocity="2.0" lower="0" upper="3.14" />
    </joint>
    <link name="link2">
        <visual>
            <origin xyz="0 0 0.75" rpy="0 0 0" />
            <geometry>
                <cylinder radius="0.7" length="1.5" />
            </geometry>
            <material name="gray">
                <color rgba="1 0 0 1" />
            </material>
        </visual>
        <collision>
            <origin xyz="0 0 0.75" rpy="0 0 0" />
            <geometry>
                <cylinder radius="0.7" length="1.5" />
            </geometry>
        </collision>
        <inertial>
            <mass value="0.1" />
            <origin xyz="0 0 0" rpy="0 0 0" />
            <inertia ixx="0.03" iyy="0.03" izz="0.03" ixy="0.0" ixz="0.0" iyz="0.0" />
        </inertial>
    </link>
    <joint name="joint3" type="revolute">
        <parent link="link2" />
        <child link="link3" />
        <origin xyz="0 0 1.5" />
        <axis xyz="1 0 0" />
        <limit effort="5" velocity="2.0" lower="0" upper="1.77" />
    </joint>
    <link name="link3">
        <visual>
            <origin xyz="0 0 1.5" rpy="0 0 0" />
            <geometry>
                <box size="1.2 1.2 3" />
            </geometry>
            <material name="blue">
                <color rgba="1 0 0 1" />
            </material>
        </visual>
        <collision>
            <origin xyz="0 0 1.5" rpy="0 0 0" />
            <geometry>
                <box size="1.2 1.2 3" />
            </geometry>
        </collision>
        <inertial>
            <mass value="0.1" />
            <origin xyz="0 0 0" rpy="0 0 0" />
            <inertia ixx="0.03" iyy="0.03" izz="0.03" ixy="0.0" ixz="0.0" iyz="0.0" />
        </inertial>
    </link>
    <joint name="joint4" type="revolute">
        <parent link="link3" />
        <child link="link4" />
        <origin xyz="0 0 3" />
        <axis xyz="1 0 0" />
        <limit effort="5" velocity="2.0" lower="0" upper="1.77" />
    </joint>
    <link name="link4">
        <visual>
            <origin xyz="0 0 0.5" rpy="0 0 0" />
            <geometry>
                <cylinder radius="0.5" length="1" />
            </geometry>
            <material name="gray">
                <color rgba="1 1 0.5 1" />
            </material>
        </visual>
        <collision>
            <origin xyz="0 0 0.5" rpy="0 0 0" />
            <geometry>
                <cylinder radius="0.5" length="1" />
            </geometry>
        </collision>
        <inertial>
            <mass value="0.1" />
            <origin xyz="0 0 0" rpy="0 0 0" />
            <inertia ixx="0.03" iyy="0.03" izz="0.03" ixy="0.0" ixz="0.0" iyz="0.0" />
        </inertial>
    </link>
    <joint name="joint5" type="revolute">
        <parent link="link4" />
        <child link="link5" />
        <origin xyz="0 0 1.5" />
        <axis xyz="0 0 1" />
        <limit effort="5" velocity="2.0" lower="0" upper="3.14" />
    </joint>
    <link name="link5">
        <visual>
            <geometry>
                <cylinder radius="0.5" length="1" />
            </geometry>
            <material name="gray">
                <color rgba="1 1 0.5 1" />
            </material>
        </visual>
        <collision>
            <geometry>
                <cylinder radius="0.5" length="1" />
            </geometry>
        </collision>
        <inertial>
            <mass value="0.1" />
            <origin xyz="0 0 0" rpy="0 0 0" />
            <inertia ixx="0.03" iyy="0.03" izz="0.03" ixy="0.0" ixz="0.0" iyz="0.0" />
        </inertial>
    </link>
    <joint name="joint6" type="revolute">
        <parent link="link5" />
        <child link="link6" />
        <origin xyz="0 0 0.5" />
        <axis xyz="1 0 0" />
        <limit effort="5" velocity="2.0" lower="0" upper="1.77" />
    </joint>
    <link name="link6">
        <visual>
            <origin xyz="0 0 0.4" rpy="0 0 0" />
            <geometry>
                <box size="0.8 0.8 0.8" />
            </geometry>
            <material name="blue">
                <color rgba="1 0 0 1" />
            </material>
        </visual>
        <collision>
            <origin xyz="0 0 0.4" rpy="0 0 0" />
            <geometry>
                <box size="0.8 0.8 0.8" />
            </geometry>
        </collision>
        <inertial>
            <mass value="0.1" />
            <origin xyz="0 0 0" rpy="0 0 0" />
            <inertia ixx="0.03" iyy="0.03" izz="0.03" ixy="0.0" ixz="0.0" iyz="0.0" />
        </inertial>
    </link>
    <joint name="joint7" type="revolute">
        <parent link="link6" />
        <child link="link7" />
        <origin xyz="0 0 0.8" />
        <axis xyz="0 0 1" />
        <limit effort="5" velocity="2.0" lower="0" upper="3.14" />
    </joint>
    <link name="link7">
        <visual>
            <origin xyz="0 0 0.35" rpy="0 0 0" />
            <geometry>
                <cylinder radius="0.4" length="0.7" />
            </geometry>
            <material name="gray">
                <color rgba="1 1 0.5 1" />
            </material>
        </visual>
        <collision>
            <origin xyz="0 0 0.35" rpy="0 0 0" />
            <geometry>
                <cylinder radius="0.4" length="0.7" />
            </geometry>
        </collision>
        <inertial>
            <mass value="0.1" />
            <origin xyz="0 0 0" rpy="0 0 0" />
            <inertia ixx="0.03" iyy="0.03" izz="0.03" ixy="0.0" ixz="0.0" iyz="0.0" />
        </inertial>
    </link>
    <joint name="joint8" type="fixed">
        <parent link="link7" />
        <child link="big_red_box" />
        <origin xyz="0 0 0.5" />
        <axis xyz="1 0 0" />
        <limit effort="5" velocity="2.0" lower="0" upper="1.77" />
    </joint>
    <link name="big_red_box">
        <visual>
            <origin xyz="0 0 0.4" rpy="0 0 0" />
            <geometry>
                <box size="0.2 0.2 0.4" />
            </geometry>
            <material name="blue">
                <color rgba="1 0 0 1" />
            </material>
        </visual>
        <collision>
            <origin xyz="0 0 0.4" rpy="0 0 0" />
            <geometry>
                <box size="0.2 0.2 0.4" />
            </geometry>
        </collision>
        <inertial>
            <mass value="0.1" />
            <origin xyz="0 0 0" rpy="0 0 0" />
            <inertia ixx="0.03" iyy="0.03" izz="0.03" ixy="0.0" ixz="0.0" iyz="0.0" />
        </inertial>
    </link>
    <joint name="joint9" type="prismatic">
        <parent link="big_red_box" />
        <child link="link9" />
        <origin xyz="0 0 0.6" />
        <axis xyz="1 0 0" />
        <limit effort="5" velocity="0.1" lower="0" upper="0.25" />
    </joint>
    <link name="link9">
        <visual>
            <origin xyz="0.1 0 0.25" rpy="0 0 0" />
            <geometry>
                <box size="0.05 0.05 0.5" />
            </geometry>
            <material name="blue">
                <color rgba="1 0 0 1" />
            </material>
        </visual>
        <collision>
            <origin xyz="0.1 0 0.25" rpy="0 0 0" />
            <geometry>
                <box size="0.05 0.05 0.5" />
            </geometry>
        </collision>
        <inertial>
            <mass value="0.1" />
            <origin xyz="0 0 0" rpy="0 0 0" />
            <inertia ixx="0.03" iyy="0.03" izz="0.03" ixy="0.0" ixz="0.0" iyz="0.0" />
        </inertial>
    </link>
    <link name="link10">
        <visual>
            <origin xyz="-0.1 0 0.25" rpy="0 0 0" />
            <geometry>
                <box size="0.05 0.05 0.5" />
            </geometry>
            <material name="blue">
                <color rgba="1 0 0 1" />
            </material>
        </visual>
        <collision>
            <origin xyz="-0.1 0 0.25" rpy="0 0 0" />
            <geometry>
                <box size="0.05 0.05 0.5" />
            </geometry>
        </collision>
        <inertial>
            <mass value="0.1" />
            <origin xyz="0 0 0" rpy="0 0 0" />
            <inertia ixx="0.03" iyy="0.03" izz="0.03" ixy="0.0" ixz="0.0" iyz="0.0" />
        </inertial>
    </link>
    <joint name="joint10" type="prismatic">
        <parent link="big_red_box" />
        <child link="link10" />
        <origin xyz="0 0 0.6" />
        <axis xyz="-1 0 0" />
        <limit effort="5" velocity="2.0" lower="0" upper="0.25" />
        <mimic joint="joint9" multiplier="1" offset="0" />
    </joint>
    <transmission name="trans_joint2">
        <type>transmission_interface/SimpleTransmission</type>
        <joint name="joint2">
            <hardwareInterface>hardware_interface/PositionJointInterface</hardwareInterface>
        </joint>
        <actuator name="joint2_motor">
            <hardwareInterface>hardware_interface/PositionJointInterface</hardwareInterface>
            <mechanicalReduction>1</mechanicalReduction>
        </actuator>
    </transmission>
    <transmission name="trans_joint3">
        <type>transmission_interface/SimpleTransmission</type>
        <joint name="joint3">
            <hardwareInterface>hardware_interface/PositionJointInterface</hardwareInterface>
        </joint>
        <actuator name="joint3_motor">
            <hardwareInterface>hardware_interface/PositionJointInterface</hardwareInterface>
            <mechanicalReduction>1</mechanicalReduction>
        </actuator>
    </transmission>
    <transmission name="trans_joint4">
        <type>transmission_interface/SimpleTransmission</type>
        <joint name="joint4">
            <hardwareInterface>hardware_interface/PositionJointInterface</hardwareInterface>
        </joint>
        <actuator name="joint4_motor">
            <hardwareInterface>hardware_interface/PositionJointInterface</hardwareInterface>
            <mechanicalReduction>1</mechanicalReduction>
        </actuator>
    </transmission>
    <transmission name="trans_joint5">
        <type>transmission_interface/SimpleTransmission</type>
        <joint name="joint5">
            <hardwareInterface>hardware_interface/PositionJointInterface</hardwareInterface>
        </joint>
        <actuator name="joint5_motor">
            <hardwareInterface>hardware_interface/PositionJointInterface</hardwareInterface>
            <mechanicalReduction>1</mechanicalReduction>
        </actuator>
    </transmission>
    <transmission name="trans_joint6">
        <type>transmission_interface/SimpleTransmission</type>
        <joint name="joint6">
            <hardwareInterface>hardware_interface/PositionJointInterface</hardwareInterface>
        </joint>
        <actuator name="joint6_motor">
            <hardwareInterface>hardware_interface/PositionJointInterface</hardwareInterface>
            <mechanicalReduction>1</mechanicalReduction>
        </actuator>
    </transmission>
    <transmission name="trans_joint7">
        <type>transmission_interface/SimpleTransmission</type>
        <joint name="joint7">
            <hardwareInterface>hardware_interface/PositionJointInterface</hardwareInterface>
        </joint>
        <actuator name="joint7_motor">
            <hardwareInterface>hardware_interface/PositionJointInterface</hardwareInterface>
            <mechanicalReduction>1</mechanicalReduction>
        </actuator>
    </transmission>
    <transmission name="trans_joint9">
        <type>transmission_interface/SimpleTransmission</type>
        <joint name="joint9">
            <hardwareInterface>hardware_interface/EffortJointInterface</hardwareInterface>
        </joint>
        <actuator name="joint9_motor">
            <hardwareInterface>hardware_interface/EffortJointInterface</hardwareInterface>
            <mechanicalReduction>1</mechanicalReduction>
        </actuator>
    </transmission>
    <transmission name="trans_joint10">
        <type>transmission_interface/SimpleTransmission</type>
        <joint name="joint10">
            <hardwareInterface>hardware_interface/EffortJointInterface</hardwareInterface>
        </joint>
        <actuator name="joint10_motor">
            <hardwareInterface>hardware_interface/EffortJointInterface</hardwareInterface>
            <mechanicalReduction>1</mechanicalReduction>
        </actuator>
    </transmission>
    <gazebo>
        <plugin name="gazebo_ros_control" filename="libgazebo_ros_control.so">
            <robotNamespace>/</robotNamespace>
        </plugin>
    </gazebo>
</robot>

